<?xml version="1.0" encoding="UTF-8"?>
<testng-results skipped="0" failed="26" ignored="0" total="27" passed="1">
  <reporter-output>
  </reporter-output>
  <suite name="TestNGSuite" duration-ms="69066" started-at="2019-12-18T08:01:55Z" finished-at="2019-12-18T08:03:04Z">
    <groups>
    </groups>
    <test name="test2" duration-ms="69066" started-at="2019-12-18T08:01:55Z" finished-at="2019-12-18T08:03:04Z">
      <class name="com.edu.lijiaqi.reim.Process">
        <test-method status="PASS" signature="doBeforeClass()[pri:0, instance:com.edu.lijiaqi.reim.Process@546a03af]" name="doBeforeClass" is-config="true" duration-ms="5348" started-at="2019-12-18T08:02:26Z" finished-at="2019-12-18T08:02:32Z">
          <reporter-output>
          </reporter-output>
        </test-method> <!-- doBeforeClass -->
        <test-method status="FAIL" signature="processAdd(java.lang.String, java.lang.String)[pri:0, instance:com.edu.lijiaqi.reim.Process@546a03af]" name="processAdd" duration-ms="80" started-at="2019-12-18T08:02:32Z" description="审核人员分组新增组" data-provider="data4" finished-at="2019-12-18T08:02:32Z">
          <params>
            <param index="0">
              <value>
                <![CDATA[审核人员分组2]]>
              </value>
            </param>
            <param index="1">
              <value>
                <![CDATA[group2]]>
              </value>
            </param>
          </params>
          <exception class="java.lang.AssertionError">
            <message>
              <![CDATA[expected [true] but found [false]]]>
            </message>
            <full-stacktrace>
              <![CDATA[java.lang.AssertionError: expected [true] but found [false]
at org.testng.Assert.fail(Assert.java:96)
at org.testng.Assert.failNotEquals(Assert.java:776)
at org.testng.Assert.assertTrue(Assert.java:44)
at org.testng.Assert.assertTrue(Assert.java:54)
at com.edu.lijiaqi.reim.Process.processAdd(Unknown Source)
at sun.reflect.NativeMethodAccessorImpl.invoke0(Native Method)
at sun.reflect.NativeMethodAccessorImpl.invoke(NativeMethodAccessorImpl.java:62)
at sun.reflect.DelegatingMethodAccessorImpl.invoke(DelegatingMethodAccessorImpl.java:43)
at java.lang.reflect.Method.invoke(Method.java:498)
at org.testng.internal.MethodInvocationHelper.invokeMethod(MethodInvocationHelper.java:124)
at org.testng.internal.Invoker.invokeMethod(Invoker.java:583)
at org.testng.internal.Invoker.invokeTestMethod(Invoker.java:719)
at org.testng.internal.Invoker.invokeTestMethods(Invoker.java:989)
at org.testng.internal.TestMethodWorker.invokeTestMethods(TestMethodWorker.java:125)
at org.testng.internal.TestMethodWorker.run(TestMethodWorker.java:109)
at org.testng.TestRunner.privateRun(TestRunner.java:648)
at org.testng.TestRunner.run(TestRunner.java:505)
at org.testng.SuiteRunner.runTest(SuiteRunner.java:455)
at org.testng.SuiteRunner.runSequentially(SuiteRunner.java:450)
at org.testng.SuiteRunner.privateRun(SuiteRunner.java:415)
at org.testng.SuiteRunner.run(SuiteRunner.java:364)
at org.testng.SuiteRunnerWorker.runSuite(SuiteRunnerWorker.java:52)
at org.testng.SuiteRunnerWorker.run(SuiteRunnerWorker.java:84)
at org.testng.TestNG.runSuitesSequentially(TestNG.java:1208)
at org.testng.TestNG.runSuitesLocally(TestNG.java:1137)
at org.testng.TestNG.runSuites(TestNG.java:1049)
at org.testng.TestNG.run(TestNG.java:1017)
at org.testng.TestNG.privateMain(TestNG.java:1354)
at org.testng.TestNG.main(TestNG.java:1323)
]]>
            </full-stacktrace>
          </exception> <!-- java.lang.AssertionError -->
          <reporter-output>
          </reporter-output>
        </test-method> <!-- processAdd -->
        <test-method status="FAIL" signature="processAdd(java.lang.String, java.lang.String)[pri:0, instance:com.edu.lijiaqi.reim.Process@546a03af]" name="processAdd" duration-ms="74" started-at="2019-12-18T08:02:32Z" description="审核人员分组新增组" data-provider="data4" finished-at="2019-12-18T08:02:32Z">
          <params>
            <param index="0">
              <value>
                <![CDATA[审核人员分组3]]>
              </value>
            </param>
            <param index="1">
              <value>
                <![CDATA[group2]]>
              </value>
            </param>
          </params>
          <exception class="java.lang.AssertionError">
            <message>
              <![CDATA[expected [true] but found [false]]]>
            </message>
            <full-stacktrace>
              <![CDATA[java.lang.AssertionError: expected [true] but found [false]
at org.testng.Assert.fail(Assert.java:96)
at org.testng.Assert.failNotEquals(Assert.java:776)
at org.testng.Assert.assertTrue(Assert.java:44)
at org.testng.Assert.assertTrue(Assert.java:54)
at com.edu.lijiaqi.reim.Process.processAdd(Unknown Source)
at sun.reflect.NativeMethodAccessorImpl.invoke0(Native Method)
at sun.reflect.NativeMethodAccessorImpl.invoke(NativeMethodAccessorImpl.java:62)
at sun.reflect.DelegatingMethodAccessorImpl.invoke(DelegatingMethodAccessorImpl.java:43)
at java.lang.reflect.Method.invoke(Method.java:498)
at org.testng.internal.MethodInvocationHelper.invokeMethod(MethodInvocationHelper.java:124)
at org.testng.internal.Invoker.invokeMethod(Invoker.java:583)
at org.testng.internal.Invoker.invokeTestMethod(Invoker.java:719)
at org.testng.internal.Invoker.invokeTestMethods(Invoker.java:989)
at org.testng.internal.TestMethodWorker.invokeTestMethods(TestMethodWorker.java:125)
at org.testng.internal.TestMethodWorker.run(TestMethodWorker.java:109)
at org.testng.TestRunner.privateRun(TestRunner.java:648)
at org.testng.TestRunner.run(TestRunner.java:505)
at org.testng.SuiteRunner.runTest(SuiteRunner.java:455)
at org.testng.SuiteRunner.runSequentially(SuiteRunner.java:450)
at org.testng.SuiteRunner.privateRun(SuiteRunner.java:415)
at org.testng.SuiteRunner.run(SuiteRunner.java:364)
at org.testng.SuiteRunnerWorker.runSuite(SuiteRunnerWorker.java:52)
at org.testng.SuiteRunnerWorker.run(SuiteRunnerWorker.java:84)
at org.testng.TestNG.runSuitesSequentially(TestNG.java:1208)
at org.testng.TestNG.runSuitesLocally(TestNG.java:1137)
at org.testng.TestNG.runSuites(TestNG.java:1049)
at org.testng.TestNG.run(TestNG.java:1017)
at org.testng.TestNG.privateMain(TestNG.java:1354)
at org.testng.TestNG.main(TestNG.java:1323)
]]>
            </full-stacktrace>
          </exception> <!-- java.lang.AssertionError -->
          <reporter-output>
          </reporter-output>
        </test-method> <!-- processAdd -->
        <test-method status="FAIL" signature="processChange()[pri:0, instance:com.edu.lijiaqi.reim.Process@546a03af]" name="processChange" duration-ms="55" started-at="2019-12-18T08:02:32Z" description="审核人员分组修改" finished-at="2019-12-18T08:02:32Z">
          <exception class="java.lang.AssertionError">
            <message>
              <![CDATA[expected [true] but found [false]]]>
            </message>
            <full-stacktrace>
              <![CDATA[java.lang.AssertionError: expected [true] but found [false]
at org.testng.Assert.fail(Assert.java:96)
at org.testng.Assert.failNotEquals(Assert.java:776)
at org.testng.Assert.assertTrue(Assert.java:44)
at org.testng.Assert.assertTrue(Assert.java:54)
at com.edu.lijiaqi.reim.Process.processChange(Unknown Source)
at sun.reflect.NativeMethodAccessorImpl.invoke0(Native Method)
at sun.reflect.NativeMethodAccessorImpl.invoke(NativeMethodAccessorImpl.java:62)
at sun.reflect.DelegatingMethodAccessorImpl.invoke(DelegatingMethodAccessorImpl.java:43)
at java.lang.reflect.Method.invoke(Method.java:498)
at org.testng.internal.MethodInvocationHelper.invokeMethod(MethodInvocationHelper.java:124)
at org.testng.internal.Invoker.invokeMethod(Invoker.java:583)
at org.testng.internal.Invoker.invokeTestMethod(Invoker.java:719)
at org.testng.internal.Invoker.invokeTestMethods(Invoker.java:989)
at org.testng.internal.TestMethodWorker.invokeTestMethods(TestMethodWorker.java:125)
at org.testng.internal.TestMethodWorker.run(TestMethodWorker.java:109)
at org.testng.TestRunner.privateRun(TestRunner.java:648)
at org.testng.TestRunner.run(TestRunner.java:505)
at org.testng.SuiteRunner.runTest(SuiteRunner.java:455)
at org.testng.SuiteRunner.runSequentially(SuiteRunner.java:450)
at org.testng.SuiteRunner.privateRun(SuiteRunner.java:415)
at org.testng.SuiteRunner.run(SuiteRunner.java:364)
at org.testng.SuiteRunnerWorker.runSuite(SuiteRunnerWorker.java:52)
at org.testng.SuiteRunnerWorker.run(SuiteRunnerWorker.java:84)
at org.testng.TestNG.runSuitesSequentially(TestNG.java:1208)
at org.testng.TestNG.runSuitesLocally(TestNG.java:1137)
at org.testng.TestNG.runSuites(TestNG.java:1049)
at org.testng.TestNG.run(TestNG.java:1017)
at org.testng.TestNG.privateMain(TestNG.java:1354)
at org.testng.TestNG.main(TestNG.java:1323)
]]>
            </full-stacktrace>
          </exception> <!-- java.lang.AssertionError -->
          <reporter-output>
          </reporter-output>
        </test-method> <!-- processChange -->
        <test-method status="FAIL" signature="processDelete()[pri:0, instance:com.edu.lijiaqi.reim.Process@546a03af]" name="processDelete" duration-ms="21" started-at="2019-12-18T08:02:32Z" description="审核人员分组删除" finished-at="2019-12-18T08:02:32Z">
          <exception class="java.lang.AssertionError">
            <message>
              <![CDATA[expected [true] but found [false]]]>
            </message>
            <full-stacktrace>
              <![CDATA[java.lang.AssertionError: expected [true] but found [false]
at org.testng.Assert.fail(Assert.java:96)
at org.testng.Assert.failNotEquals(Assert.java:776)
at org.testng.Assert.assertTrue(Assert.java:44)
at org.testng.Assert.assertTrue(Assert.java:54)
at com.edu.lijiaqi.reim.Process.processDelete(Unknown Source)
at sun.reflect.NativeMethodAccessorImpl.invoke0(Native Method)
at sun.reflect.NativeMethodAccessorImpl.invoke(NativeMethodAccessorImpl.java:62)
at sun.reflect.DelegatingMethodAccessorImpl.invoke(DelegatingMethodAccessorImpl.java:43)
at java.lang.reflect.Method.invoke(Method.java:498)
at org.testng.internal.MethodInvocationHelper.invokeMethod(MethodInvocationHelper.java:124)
at org.testng.internal.Invoker.invokeMethod(Invoker.java:583)
at org.testng.internal.Invoker.invokeTestMethod(Invoker.java:719)
at org.testng.internal.Invoker.invokeTestMethods(Invoker.java:989)
at org.testng.internal.TestMethodWorker.invokeTestMethods(TestMethodWorker.java:125)
at org.testng.internal.TestMethodWorker.run(TestMethodWorker.java:109)
at org.testng.TestRunner.privateRun(TestRunner.java:648)
at org.testng.TestRunner.run(TestRunner.java:505)
at org.testng.SuiteRunner.runTest(SuiteRunner.java:455)
at org.testng.SuiteRunner.runSequentially(SuiteRunner.java:450)
at org.testng.SuiteRunner.privateRun(SuiteRunner.java:415)
at org.testng.SuiteRunner.run(SuiteRunner.java:364)
at org.testng.SuiteRunnerWorker.runSuite(SuiteRunnerWorker.java:52)
at org.testng.SuiteRunnerWorker.run(SuiteRunnerWorker.java:84)
at org.testng.TestNG.runSuitesSequentially(TestNG.java:1208)
at org.testng.TestNG.runSuitesLocally(TestNG.java:1137)
at org.testng.TestNG.runSuites(TestNG.java:1049)
at org.testng.TestNG.run(TestNG.java:1017)
at org.testng.TestNG.privateMain(TestNG.java:1354)
at org.testng.TestNG.main(TestNG.java:1323)
]]>
            </full-stacktrace>
          </exception> <!-- java.lang.AssertionError -->
          <reporter-output>
          </reporter-output>
        </test-method> <!-- processDelete -->
        <test-method status="PASS" signature="doAfterClass()[pri:0, instance:com.edu.lijiaqi.reim.Process@546a03af]" name="doAfterClass" is-config="true" duration-ms="3946" started-at="2019-12-18T08:02:32Z" finished-at="2019-12-18T08:02:36Z">
          <reporter-output>
          </reporter-output>
        </test-method> <!-- doAfterClass -->
      </class> <!-- com.edu.lijiaqi.reim.Process -->
      <class name="com.edu.lijiaqi.reim.ProcessTerm">
        <test-method status="PASS" signature="doBeforeClass()[pri:0, instance:com.edu.lijiaqi.reim.ProcessTerm@6ea6d14e]" name="doBeforeClass" is-config="true" duration-ms="5303" started-at="2019-12-18T08:02:55Z" finished-at="2019-12-18T08:03:00Z">
          <reporter-output>
          </reporter-output>
        </test-method> <!-- doBeforeClass -->
        <test-method status="FAIL" signature="termAdd()[pri:0, instance:com.edu.lijiaqi.reim.ProcessTerm@6ea6d14e]" name="termAdd" duration-ms="23" started-at="2019-12-18T08:03:00Z" description="筛选条件并新增" finished-at="2019-12-18T08:03:00Z">
          <exception class="java.lang.NullPointerException">
            <full-stacktrace>
              <![CDATA[java.lang.NullPointerException
at org.openqa.selenium.support.ui.Select.<init>(Select.java:45)
at com.webtest.core.WebDriverEngine.getSelect(WebDriverEngine.java:229)
at com.webtest.core.WebDriverEngine.selectByValue(WebDriverEngine.java:234)
at com.edu.lijiaqi.reim.ProcessTerm.InitDemo(Unknown Source)
at com.edu.lijiaqi.reim.ProcessTerm.termAdd(Unknown Source)
at sun.reflect.NativeMethodAccessorImpl.invoke0(Native Method)
at sun.reflect.NativeMethodAccessorImpl.invoke(NativeMethodAccessorImpl.java:62)
at sun.reflect.DelegatingMethodAccessorImpl.invoke(DelegatingMethodAccessorImpl.java:43)
at java.lang.reflect.Method.invoke(Method.java:498)
at org.testng.internal.MethodInvocationHelper.invokeMethod(MethodInvocationHelper.java:124)
at org.testng.internal.Invoker.invokeMethod(Invoker.java:583)
at org.testng.internal.Invoker.invokeTestMethod(Invoker.java:719)
at org.testng.internal.Invoker.invokeTestMethods(Invoker.java:989)
at org.testng.internal.TestMethodWorker.invokeTestMethods(TestMethodWorker.java:125)
at org.testng.internal.TestMethodWorker.run(TestMethodWorker.java:109)
at org.testng.TestRunner.privateRun(TestRunner.java:648)
at org.testng.TestRunner.run(TestRunner.java:505)
at org.testng.SuiteRunner.runTest(SuiteRunner.java:455)
at org.testng.SuiteRunner.runSequentially(SuiteRunner.java:450)
at org.testng.SuiteRunner.privateRun(SuiteRunner.java:415)
at org.testng.SuiteRunner.run(SuiteRunner.java:364)
at org.testng.SuiteRunnerWorker.runSuite(SuiteRunnerWorker.java:52)
at org.testng.SuiteRunnerWorker.run(SuiteRunnerWorker.java:84)
at org.testng.TestNG.runSuitesSequentially(TestNG.java:1208)
at org.testng.TestNG.runSuitesLocally(TestNG.java:1137)
at org.testng.TestNG.runSuites(TestNG.java:1049)
at org.testng.TestNG.run(TestNG.java:1017)
at org.testng.TestNG.privateMain(TestNG.java:1354)
at org.testng.TestNG.main(TestNG.java:1323)
]]>
            </full-stacktrace>
          </exception> <!-- java.lang.NullPointerException -->
          <reporter-output>
          </reporter-output>
        </test-method> <!-- termAdd -->
        <test-method status="FAIL" signature="termDelete()[pri:0, instance:com.edu.lijiaqi.reim.ProcessTerm@6ea6d14e]" name="termDelete" duration-ms="25" started-at="2019-12-18T08:03:00Z" description="筛选条件并删除" finished-at="2019-12-18T08:03:00Z">
          <exception class="java.lang.AssertionError">
            <message>
              <![CDATA[expected [true] but found [false]]]>
            </message>
            <full-stacktrace>
              <![CDATA[java.lang.AssertionError: expected [true] but found [false]
at org.testng.Assert.fail(Assert.java:96)
at org.testng.Assert.failNotEquals(Assert.java:776)
at org.testng.Assert.assertTrue(Assert.java:44)
at org.testng.Assert.assertTrue(Assert.java:54)
at com.edu.lijiaqi.reim.ProcessTerm.termDelete(Unknown Source)
at sun.reflect.NativeMethodAccessorImpl.invoke0(Native Method)
at sun.reflect.NativeMethodAccessorImpl.invoke(NativeMethodAccessorImpl.java:62)
at sun.reflect.DelegatingMethodAccessorImpl.invoke(DelegatingMethodAccessorImpl.java:43)
at java.lang.reflect.Method.invoke(Method.java:498)
at org.testng.internal.MethodInvocationHelper.invokeMethod(MethodInvocationHelper.java:124)
at org.testng.internal.Invoker.invokeMethod(Invoker.java:583)
at org.testng.internal.Invoker.invokeTestMethod(Invoker.java:719)
at org.testng.internal.Invoker.invokeTestMethods(Invoker.java:989)
at org.testng.internal.TestMethodWorker.invokeTestMethods(TestMethodWorker.java:125)
at org.testng.internal.TestMethodWorker.run(TestMethodWorker.java:109)
at org.testng.TestRunner.privateRun(TestRunner.java:648)
at org.testng.TestRunner.run(TestRunner.java:505)
at org.testng.SuiteRunner.runTest(SuiteRunner.java:455)
at org.testng.SuiteRunner.runSequentially(SuiteRunner.java:450)
at org.testng.SuiteRunner.privateRun(SuiteRunner.java:415)
at org.testng.SuiteRunner.run(SuiteRunner.java:364)
at org.testng.SuiteRunnerWorker.runSuite(SuiteRunnerWorker.java:52)
at org.testng.SuiteRunnerWorker.run(SuiteRunnerWorker.java:84)
at org.testng.TestNG.runSuitesSequentially(TestNG.java:1208)
at org.testng.TestNG.runSuitesLocally(TestNG.java:1137)
at org.testng.TestNG.runSuites(TestNG.java:1049)
at org.testng.TestNG.run(TestNG.java:1017)
at org.testng.TestNG.privateMain(TestNG.java:1354)
at org.testng.TestNG.main(TestNG.java:1323)
]]>
            </full-stacktrace>
          </exception> <!-- java.lang.AssertionError -->
          <reporter-output>
          </reporter-output>
        </test-method> <!-- termDelete -->
        <test-method status="PASS" signature="doAfterClass()[pri:0, instance:com.edu.lijiaqi.reim.ProcessTerm@6ea6d14e]" name="doAfterClass" is-config="true" duration-ms="3907" started-at="2019-12-18T08:03:00Z" finished-at="2019-12-18T08:03:04Z">
          <reporter-output>
          </reporter-output>
        </test-method> <!-- doAfterClass -->
      </class> <!-- com.edu.lijiaqi.reim.ProcessTerm -->
      <class name="com.edu.lijiaqi.reim.ReimSet">
        <test-method status="PASS" signature="doBeforeClass()[pri:0, instance:com.edu.lijiaqi.reim.ReimSet@7907ec20]" name="doBeforeClass" is-config="true" duration-ms="5311" started-at="2019-12-18T08:02:17Z" finished-at="2019-12-18T08:02:22Z">
          <reporter-output>
          </reporter-output>
        </test-method> <!-- doBeforeClass -->
        <test-method status="FAIL" signature="setDemo1()[pri:0, instance:com.edu.lijiaqi.reim.ReimSet@7907ec20]" name="setDemo1" duration-ms="16" started-at="2019-12-18T08:02:22Z" description="打开设置提醒" finished-at="2019-12-18T08:02:22Z">
          <exception class="java.lang.IndexOutOfBoundsException">
            <message>
              <![CDATA[Index: 1, Size: 1]]>
            </message>
            <full-stacktrace>
              <![CDATA[java.lang.IndexOutOfBoundsException: Index: 1, Size: 1
at java.util.ArrayList.rangeCheck(ArrayList.java:657)
at java.util.ArrayList.get(ArrayList.java:433)
at com.webtest.core.WebDriverEngine.switchWidow(WebDriverEngine.java:269)
at com.edu.lijiaqi.reim.ReimSet.InitDemo(Unknown Source)
at com.edu.lijiaqi.reim.ReimSet.setDemo1(Unknown Source)
at sun.reflect.NativeMethodAccessorImpl.invoke0(Native Method)
at sun.reflect.NativeMethodAccessorImpl.invoke(NativeMethodAccessorImpl.java:62)
at sun.reflect.DelegatingMethodAccessorImpl.invoke(DelegatingMethodAccessorImpl.java:43)
at java.lang.reflect.Method.invoke(Method.java:498)
at org.testng.internal.MethodInvocationHelper.invokeMethod(MethodInvocationHelper.java:124)
at org.testng.internal.Invoker.invokeMethod(Invoker.java:583)
at org.testng.internal.Invoker.invokeTestMethod(Invoker.java:719)
at org.testng.internal.Invoker.invokeTestMethods(Invoker.java:989)
at org.testng.internal.TestMethodWorker.invokeTestMethods(TestMethodWorker.java:125)
at org.testng.internal.TestMethodWorker.run(TestMethodWorker.java:109)
at org.testng.TestRunner.privateRun(TestRunner.java:648)
at org.testng.TestRunner.run(TestRunner.java:505)
at org.testng.SuiteRunner.runTest(SuiteRunner.java:455)
at org.testng.SuiteRunner.runSequentially(SuiteRunner.java:450)
at org.testng.SuiteRunner.privateRun(SuiteRunner.java:415)
at org.testng.SuiteRunner.run(SuiteRunner.java:364)
at org.testng.SuiteRunnerWorker.runSuite(SuiteRunnerWorker.java:52)
at org.testng.SuiteRunnerWorker.run(SuiteRunnerWorker.java:84)
at org.testng.TestNG.runSuitesSequentially(TestNG.java:1208)
at org.testng.TestNG.runSuitesLocally(TestNG.java:1137)
at org.testng.TestNG.runSuites(TestNG.java:1049)
at org.testng.TestNG.run(TestNG.java:1017)
at org.testng.TestNG.privateMain(TestNG.java:1354)
at org.testng.TestNG.main(TestNG.java:1323)
]]>
            </full-stacktrace>
          </exception> <!-- java.lang.IndexOutOfBoundsException -->
          <reporter-output>
          </reporter-output>
        </test-method> <!-- setDemo1 -->
        <test-method status="FAIL" signature="setDemo2(java.lang.String)[pri:0, instance:com.edu.lijiaqi.reim.ReimSet@7907ec20]" name="setDemo2" duration-ms="40" started-at="2019-12-18T08:02:22Z" description="创建会话" data-provider="data1" finished-at="2019-12-18T08:02:22Z">
          <params>
            <param index="0">
              <value>
                <![CDATA[abc]]>
              </value>
            </param>
          </params>
          <exception class="java.lang.AssertionError">
            <message>
              <![CDATA[expected [true] but found [false]]]>
            </message>
            <full-stacktrace>
              <![CDATA[java.lang.AssertionError: expected [true] but found [false]
at org.testng.Assert.fail(Assert.java:96)
at org.testng.Assert.failNotEquals(Assert.java:776)
at org.testng.Assert.assertTrue(Assert.java:44)
at org.testng.Assert.assertTrue(Assert.java:54)
at com.edu.lijiaqi.reim.ReimSet.setDemo2(Unknown Source)
at sun.reflect.NativeMethodAccessorImpl.invoke0(Native Method)
at sun.reflect.NativeMethodAccessorImpl.invoke(NativeMethodAccessorImpl.java:62)
at sun.reflect.DelegatingMethodAccessorImpl.invoke(DelegatingMethodAccessorImpl.java:43)
at java.lang.reflect.Method.invoke(Method.java:498)
at org.testng.internal.MethodInvocationHelper.invokeMethod(MethodInvocationHelper.java:124)
at org.testng.internal.Invoker.invokeMethod(Invoker.java:583)
at org.testng.internal.Invoker.invokeTestMethod(Invoker.java:719)
at org.testng.internal.Invoker.invokeTestMethods(Invoker.java:989)
at org.testng.internal.TestMethodWorker.invokeTestMethods(TestMethodWorker.java:125)
at org.testng.internal.TestMethodWorker.run(TestMethodWorker.java:109)
at org.testng.TestRunner.privateRun(TestRunner.java:648)
at org.testng.TestRunner.run(TestRunner.java:505)
at org.testng.SuiteRunner.runTest(SuiteRunner.java:455)
at org.testng.SuiteRunner.runSequentially(SuiteRunner.java:450)
at org.testng.SuiteRunner.privateRun(SuiteRunner.java:415)
at org.testng.SuiteRunner.run(SuiteRunner.java:364)
at org.testng.SuiteRunnerWorker.runSuite(SuiteRunnerWorker.java:52)
at org.testng.SuiteRunnerWorker.run(SuiteRunnerWorker.java:84)
at org.testng.TestNG.runSuitesSequentially(TestNG.java:1208)
at org.testng.TestNG.runSuitesLocally(TestNG.java:1137)
at org.testng.TestNG.runSuites(TestNG.java:1049)
at org.testng.TestNG.run(TestNG.java:1017)
at org.testng.TestNG.privateMain(TestNG.java:1354)
at org.testng.TestNG.main(TestNG.java:1323)
]]>
            </full-stacktrace>
          </exception> <!-- java.lang.AssertionError -->
          <reporter-output>
          </reporter-output>
        </test-method> <!-- setDemo2 -->
        <test-method status="FAIL" signature="setDemo2(java.lang.String)[pri:0, instance:com.edu.lijiaqi.reim.ReimSet@7907ec20]" name="setDemo2" duration-ms="32" started-at="2019-12-18T08:02:22Z" description="创建会话" data-provider="data1" finished-at="2019-12-18T08:02:22Z">
          <params>
            <param index="0">
              <value>
                <![CDATA[你好]]>
              </value>
            </param>
          </params>
          <exception class="java.lang.AssertionError">
            <message>
              <![CDATA[expected [true] but found [false]]]>
            </message>
            <full-stacktrace>
              <![CDATA[java.lang.AssertionError: expected [true] but found [false]
at org.testng.Assert.fail(Assert.java:96)
at org.testng.Assert.failNotEquals(Assert.java:776)
at org.testng.Assert.assertTrue(Assert.java:44)
at org.testng.Assert.assertTrue(Assert.java:54)
at com.edu.lijiaqi.reim.ReimSet.setDemo2(Unknown Source)
at sun.reflect.NativeMethodAccessorImpl.invoke0(Native Method)
at sun.reflect.NativeMethodAccessorImpl.invoke(NativeMethodAccessorImpl.java:62)
at sun.reflect.DelegatingMethodAccessorImpl.invoke(DelegatingMethodAccessorImpl.java:43)
at java.lang.reflect.Method.invoke(Method.java:498)
at org.testng.internal.MethodInvocationHelper.invokeMethod(MethodInvocationHelper.java:124)
at org.testng.internal.Invoker.invokeMethod(Invoker.java:583)
at org.testng.internal.Invoker.invokeTestMethod(Invoker.java:719)
at org.testng.internal.Invoker.invokeTestMethods(Invoker.java:989)
at org.testng.internal.TestMethodWorker.invokeTestMethods(TestMethodWorker.java:125)
at org.testng.internal.TestMethodWorker.run(TestMethodWorker.java:109)
at org.testng.TestRunner.privateRun(TestRunner.java:648)
at org.testng.TestRunner.run(TestRunner.java:505)
at org.testng.SuiteRunner.runTest(SuiteRunner.java:455)
at org.testng.SuiteRunner.runSequentially(SuiteRunner.java:450)
at org.testng.SuiteRunner.privateRun(SuiteRunner.java:415)
at org.testng.SuiteRunner.run(SuiteRunner.java:364)
at org.testng.SuiteRunnerWorker.runSuite(SuiteRunnerWorker.java:52)
at org.testng.SuiteRunnerWorker.run(SuiteRunnerWorker.java:84)
at org.testng.TestNG.runSuitesSequentially(TestNG.java:1208)
at org.testng.TestNG.runSuitesLocally(TestNG.java:1137)
at org.testng.TestNG.runSuites(TestNG.java:1049)
at org.testng.TestNG.run(TestNG.java:1017)
at org.testng.TestNG.privateMain(TestNG.java:1354)
at org.testng.TestNG.main(TestNG.java:1323)
]]>
            </full-stacktrace>
          </exception> <!-- java.lang.AssertionError -->
          <reporter-output>
          </reporter-output>
        </test-method> <!-- setDemo2 -->
        <test-method status="FAIL" signature="setDemo2(java.lang.String)[pri:0, instance:com.edu.lijiaqi.reim.ReimSet@7907ec20]" name="setDemo2" duration-ms="30" started-at="2019-12-18T08:02:22Z" description="创建会话" data-provider="data1" finished-at="2019-12-18T08:02:22Z">
          <params>
            <param index="0">
              <value>
                <![CDATA[你a@<script>]]>
              </value>
            </param>
          </params>
          <exception class="java.lang.AssertionError">
            <message>
              <![CDATA[expected [true] but found [false]]]>
            </message>
            <full-stacktrace>
              <![CDATA[java.lang.AssertionError: expected [true] but found [false]
at org.testng.Assert.fail(Assert.java:96)
at org.testng.Assert.failNotEquals(Assert.java:776)
at org.testng.Assert.assertTrue(Assert.java:44)
at org.testng.Assert.assertTrue(Assert.java:54)
at com.edu.lijiaqi.reim.ReimSet.setDemo2(Unknown Source)
at sun.reflect.NativeMethodAccessorImpl.invoke0(Native Method)
at sun.reflect.NativeMethodAccessorImpl.invoke(NativeMethodAccessorImpl.java:62)
at sun.reflect.DelegatingMethodAccessorImpl.invoke(DelegatingMethodAccessorImpl.java:43)
at java.lang.reflect.Method.invoke(Method.java:498)
at org.testng.internal.MethodInvocationHelper.invokeMethod(MethodInvocationHelper.java:124)
at org.testng.internal.Invoker.invokeMethod(Invoker.java:583)
at org.testng.internal.Invoker.invokeTestMethod(Invoker.java:719)
at org.testng.internal.Invoker.invokeTestMethods(Invoker.java:989)
at org.testng.internal.TestMethodWorker.invokeTestMethods(TestMethodWorker.java:125)
at org.testng.internal.TestMethodWorker.run(TestMethodWorker.java:109)
at org.testng.TestRunner.privateRun(TestRunner.java:648)
at org.testng.TestRunner.run(TestRunner.java:505)
at org.testng.SuiteRunner.runTest(SuiteRunner.java:455)
at org.testng.SuiteRunner.runSequentially(SuiteRunner.java:450)
at org.testng.SuiteRunner.privateRun(SuiteRunner.java:415)
at org.testng.SuiteRunner.run(SuiteRunner.java:364)
at org.testng.SuiteRunnerWorker.runSuite(SuiteRunnerWorker.java:52)
at org.testng.SuiteRunnerWorker.run(SuiteRunnerWorker.java:84)
at org.testng.TestNG.runSuitesSequentially(TestNG.java:1208)
at org.testng.TestNG.runSuitesLocally(TestNG.java:1137)
at org.testng.TestNG.runSuites(TestNG.java:1049)
at org.testng.TestNG.run(TestNG.java:1017)
at org.testng.TestNG.privateMain(TestNG.java:1354)
at org.testng.TestNG.main(TestNG.java:1323)
]]>
            </full-stacktrace>
          </exception> <!-- java.lang.AssertionError -->
          <reporter-output>
          </reporter-output>
        </test-method> <!-- setDemo2 -->
        <test-method status="FAIL" signature="setDemo3()[pri:0, instance:com.edu.lijiaqi.reim.ReimSet@7907ec20]" name="setDemo3" duration-ms="12" started-at="2019-12-18T08:02:22Z" description="刷新reim页面" finished-at="2019-12-18T08:02:22Z">
          <exception class="java.lang.AssertionError">
            <message>
              <![CDATA[expected [true] but found [false]]]>
            </message>
            <full-stacktrace>
              <![CDATA[java.lang.AssertionError: expected [true] but found [false]
at org.testng.Assert.fail(Assert.java:96)
at org.testng.Assert.failNotEquals(Assert.java:776)
at org.testng.Assert.assertTrue(Assert.java:44)
at org.testng.Assert.assertTrue(Assert.java:54)
at com.edu.lijiaqi.reim.ReimSet.setDemo3(Unknown Source)
at sun.reflect.NativeMethodAccessorImpl.invoke0(Native Method)
at sun.reflect.NativeMethodAccessorImpl.invoke(NativeMethodAccessorImpl.java:62)
at sun.reflect.DelegatingMethodAccessorImpl.invoke(DelegatingMethodAccessorImpl.java:43)
at java.lang.reflect.Method.invoke(Method.java:498)
at org.testng.internal.MethodInvocationHelper.invokeMethod(MethodInvocationHelper.java:124)
at org.testng.internal.Invoker.invokeMethod(Invoker.java:583)
at org.testng.internal.Invoker.invokeTestMethod(Invoker.java:719)
at org.testng.internal.Invoker.invokeTestMethods(Invoker.java:989)
at org.testng.internal.TestMethodWorker.invokeTestMethods(TestMethodWorker.java:125)
at org.testng.internal.TestMethodWorker.run(TestMethodWorker.java:109)
at org.testng.TestRunner.privateRun(TestRunner.java:648)
at org.testng.TestRunner.run(TestRunner.java:505)
at org.testng.SuiteRunner.runTest(SuiteRunner.java:455)
at org.testng.SuiteRunner.runSequentially(SuiteRunner.java:450)
at org.testng.SuiteRunner.privateRun(SuiteRunner.java:415)
at org.testng.SuiteRunner.run(SuiteRunner.java:364)
at org.testng.SuiteRunnerWorker.runSuite(SuiteRunnerWorker.java:52)
at org.testng.SuiteRunnerWorker.run(SuiteRunnerWorker.java:84)
at org.testng.TestNG.runSuitesSequentially(TestNG.java:1208)
at org.testng.TestNG.runSuitesLocally(TestNG.java:1137)
at org.testng.TestNG.runSuites(TestNG.java:1049)
at org.testng.TestNG.run(TestNG.java:1017)
at org.testng.TestNG.privateMain(TestNG.java:1354)
at org.testng.TestNG.main(TestNG.java:1323)
]]>
            </full-stacktrace>
          </exception> <!-- java.lang.AssertionError -->
          <reporter-output>
          </reporter-output>
        </test-method> <!-- setDemo3 -->
        <test-method status="FAIL" signature="setDemo4()[pri:0, instance:com.edu.lijiaqi.reim.ReimSet@7907ec20]" name="setDemo4" duration-ms="24" started-at="2019-12-18T08:02:22Z" description="组织机构模块功能是否正常" finished-at="2019-12-18T08:02:22Z">
          <exception class="java.lang.IndexOutOfBoundsException">
            <message>
              <![CDATA[Index: 1, Size: 1]]>
            </message>
            <full-stacktrace>
              <![CDATA[java.lang.IndexOutOfBoundsException: Index: 1, Size: 1
at java.util.ArrayList.rangeCheck(ArrayList.java:657)
at java.util.ArrayList.get(ArrayList.java:433)
at com.webtest.core.WebDriverEngine.switchWidow(WebDriverEngine.java:269)
at com.edu.lijiaqi.reim.ReimSet.setDemo4(Unknown Source)
at sun.reflect.NativeMethodAccessorImpl.invoke0(Native Method)
at sun.reflect.NativeMethodAccessorImpl.invoke(NativeMethodAccessorImpl.java:62)
at sun.reflect.DelegatingMethodAccessorImpl.invoke(DelegatingMethodAccessorImpl.java:43)
at java.lang.reflect.Method.invoke(Method.java:498)
at org.testng.internal.MethodInvocationHelper.invokeMethod(MethodInvocationHelper.java:124)
at org.testng.internal.Invoker.invokeMethod(Invoker.java:583)
at org.testng.internal.Invoker.invokeTestMethod(Invoker.java:719)
at org.testng.internal.Invoker.invokeTestMethods(Invoker.java:989)
at org.testng.internal.TestMethodWorker.invokeTestMethods(TestMethodWorker.java:125)
at org.testng.internal.TestMethodWorker.run(TestMethodWorker.java:109)
at org.testng.TestRunner.privateRun(TestRunner.java:648)
at org.testng.TestRunner.run(TestRunner.java:505)
at org.testng.SuiteRunner.runTest(SuiteRunner.java:455)
at org.testng.SuiteRunner.runSequentially(SuiteRunner.java:450)
at org.testng.SuiteRunner.privateRun(SuiteRunner.java:415)
at org.testng.SuiteRunner.run(SuiteRunner.java:364)
at org.testng.SuiteRunnerWorker.runSuite(SuiteRunnerWorker.java:52)
at org.testng.SuiteRunnerWorker.run(SuiteRunnerWorker.java:84)
at org.testng.TestNG.runSuitesSequentially(TestNG.java:1208)
at org.testng.TestNG.runSuitesLocally(TestNG.java:1137)
at org.testng.TestNG.runSuites(TestNG.java:1049)
at org.testng.TestNG.run(TestNG.java:1017)
at org.testng.TestNG.privateMain(TestNG.java:1354)
at org.testng.TestNG.main(TestNG.java:1323)
]]>
            </full-stacktrace>
          </exception> <!-- java.lang.IndexOutOfBoundsException -->
          <reporter-output>
          </reporter-output>
        </test-method> <!-- setDemo4 -->
        <test-method status="PASS" signature="doAfterClass()[pri:0, instance:com.edu.lijiaqi.reim.ReimSet@7907ec20]" name="doAfterClass" is-config="true" duration-ms="3912" started-at="2019-12-18T08:02:22Z" finished-at="2019-12-18T08:02:26Z">
          <reporter-output>
          </reporter-output>
        </test-method> <!-- doAfterClass -->
      </class> <!-- com.edu.lijiaqi.reim.ReimSet -->
      <class name="com.edu.lijiaqi.reim.ProcessData">
        <test-method status="PASS" signature="doBeforeClass()[pri:0, instance:com.edu.lijiaqi.reim.ProcessData@721e0f4f]" name="doBeforeClass" is-config="true" duration-ms="5298" started-at="2019-12-18T08:02:36Z" finished-at="2019-12-18T08:02:41Z">
          <reporter-output>
          </reporter-output>
        </test-method> <!-- doBeforeClass -->
        <test-method status="FAIL" signature="dataAdd1()[pri:0, instance:com.edu.lijiaqi.reim.ProcessData@721e0f4f]" name="dataAdd1" duration-ms="19" started-at="2019-12-18T08:02:41Z" description="数据新增" finished-at="2019-12-18T08:02:41Z">
          <exception class="java.lang.NullPointerException">
            <full-stacktrace>
              <![CDATA[java.lang.NullPointerException
at java.util.Objects.requireNonNull(Objects.java:203)
at org.openqa.selenium.interactions.PointerInput$Origin.fromElement(PointerInput.java:222)
at org.openqa.selenium.interactions.Actions.moveInTicks(Actions.java:416)
at org.openqa.selenium.interactions.Actions.doubleClick(Actions.java:361)
at com.webtest.core.WebDriverEngine.doubleClick(WebDriverEngine.java:163)
at com.edu.lijiaqi.reim.ProcessData.dataAdd1(Unknown Source)
at sun.reflect.NativeMethodAccessorImpl.invoke0(Native Method)
at sun.reflect.NativeMethodAccessorImpl.invoke(NativeMethodAccessorImpl.java:62)
at sun.reflect.DelegatingMethodAccessorImpl.invoke(DelegatingMethodAccessorImpl.java:43)
at java.lang.reflect.Method.invoke(Method.java:498)
at org.testng.internal.MethodInvocationHelper.invokeMethod(MethodInvocationHelper.java:124)
at org.testng.internal.Invoker.invokeMethod(Invoker.java:583)
at org.testng.internal.Invoker.invokeTestMethod(Invoker.java:719)
at org.testng.internal.Invoker.invokeTestMethods(Invoker.java:989)
at org.testng.internal.TestMethodWorker.invokeTestMethods(TestMethodWorker.java:125)
at org.testng.internal.TestMethodWorker.run(TestMethodWorker.java:109)
at org.testng.TestRunner.privateRun(TestRunner.java:648)
at org.testng.TestRunner.run(TestRunner.java:505)
at org.testng.SuiteRunner.runTest(SuiteRunner.java:455)
at org.testng.SuiteRunner.runSequentially(SuiteRunner.java:450)
at org.testng.SuiteRunner.privateRun(SuiteRunner.java:415)
at org.testng.SuiteRunner.run(SuiteRunner.java:364)
at org.testng.SuiteRunnerWorker.runSuite(SuiteRunnerWorker.java:52)
at org.testng.SuiteRunnerWorker.run(SuiteRunnerWorker.java:84)
at org.testng.TestNG.runSuitesSequentially(TestNG.java:1208)
at org.testng.TestNG.runSuitesLocally(TestNG.java:1137)
at org.testng.TestNG.runSuites(TestNG.java:1049)
at org.testng.TestNG.run(TestNG.java:1017)
at org.testng.TestNG.privateMain(TestNG.java:1354)
at org.testng.TestNG.main(TestNG.java:1323)
]]>
            </full-stacktrace>
          </exception> <!-- java.lang.NullPointerException -->
          <reporter-output>
          </reporter-output>
        </test-method> <!-- dataAdd1 -->
        <test-method status="FAIL" signature="dataAdd2()[pri:0, instance:com.edu.lijiaqi.reim.ProcessData@721e0f4f]" name="dataAdd2" duration-ms="6" started-at="2019-12-18T08:02:41Z" description="数据新增只填名称" finished-at="2019-12-18T08:02:41Z">
          <exception class="java.lang.NullPointerException">
            <full-stacktrace>
              <![CDATA[java.lang.NullPointerException
at java.util.Objects.requireNonNull(Objects.java:203)
at org.openqa.selenium.interactions.PointerInput$Origin.fromElement(PointerInput.java:222)
at org.openqa.selenium.interactions.Actions.moveInTicks(Actions.java:416)
at org.openqa.selenium.interactions.Actions.doubleClick(Actions.java:361)
at com.webtest.core.WebDriverEngine.doubleClick(WebDriverEngine.java:163)
at com.edu.lijiaqi.reim.ProcessData.dataAdd2(Unknown Source)
at sun.reflect.NativeMethodAccessorImpl.invoke0(Native Method)
at sun.reflect.NativeMethodAccessorImpl.invoke(NativeMethodAccessorImpl.java:62)
at sun.reflect.DelegatingMethodAccessorImpl.invoke(DelegatingMethodAccessorImpl.java:43)
at java.lang.reflect.Method.invoke(Method.java:498)
at org.testng.internal.MethodInvocationHelper.invokeMethod(MethodInvocationHelper.java:124)
at org.testng.internal.Invoker.invokeMethod(Invoker.java:583)
at org.testng.internal.Invoker.invokeTestMethod(Invoker.java:719)
at org.testng.internal.Invoker.invokeTestMethods(Invoker.java:989)
at org.testng.internal.TestMethodWorker.invokeTestMethods(TestMethodWorker.java:125)
at org.testng.internal.TestMethodWorker.run(TestMethodWorker.java:109)
at org.testng.TestRunner.privateRun(TestRunner.java:648)
at org.testng.TestRunner.run(TestRunner.java:505)
at org.testng.SuiteRunner.runTest(SuiteRunner.java:455)
at org.testng.SuiteRunner.runSequentially(SuiteRunner.java:450)
at org.testng.SuiteRunner.privateRun(SuiteRunner.java:415)
at org.testng.SuiteRunner.run(SuiteRunner.java:364)
at org.testng.SuiteRunnerWorker.runSuite(SuiteRunnerWorker.java:52)
at org.testng.SuiteRunnerWorker.run(SuiteRunnerWorker.java:84)
at org.testng.TestNG.runSuitesSequentially(TestNG.java:1208)
at org.testng.TestNG.runSuitesLocally(TestNG.java:1137)
at org.testng.TestNG.runSuites(TestNG.java:1049)
at org.testng.TestNG.run(TestNG.java:1017)
at org.testng.TestNG.privateMain(TestNG.java:1354)
at org.testng.TestNG.main(TestNG.java:1323)
]]>
            </full-stacktrace>
          </exception> <!-- java.lang.NullPointerException -->
          <reporter-output>
          </reporter-output>
        </test-method> <!-- dataAdd2 -->
        <test-method status="FAIL" signature="dataDelete()[pri:0, instance:com.edu.lijiaqi.reim.ProcessData@721e0f4f]" name="dataDelete" duration-ms="5" started-at="2019-12-18T08:02:41Z" description="数据删除" finished-at="2019-12-18T08:02:41Z">
          <exception class="java.lang.NullPointerException">
            <full-stacktrace>
              <![CDATA[java.lang.NullPointerException
at java.util.Objects.requireNonNull(Objects.java:203)
at org.openqa.selenium.interactions.PointerInput$Origin.fromElement(PointerInput.java:222)
at org.openqa.selenium.interactions.Actions.moveInTicks(Actions.java:416)
at org.openqa.selenium.interactions.Actions.doubleClick(Actions.java:361)
at com.webtest.core.WebDriverEngine.doubleClick(WebDriverEngine.java:163)
at com.edu.lijiaqi.reim.ProcessData.dataDelete(Unknown Source)
at sun.reflect.NativeMethodAccessorImpl.invoke0(Native Method)
at sun.reflect.NativeMethodAccessorImpl.invoke(NativeMethodAccessorImpl.java:62)
at sun.reflect.DelegatingMethodAccessorImpl.invoke(DelegatingMethodAccessorImpl.java:43)
at java.lang.reflect.Method.invoke(Method.java:498)
at org.testng.internal.MethodInvocationHelper.invokeMethod(MethodInvocationHelper.java:124)
at org.testng.internal.Invoker.invokeMethod(Invoker.java:583)
at org.testng.internal.Invoker.invokeTestMethod(Invoker.java:719)
at org.testng.internal.Invoker.invokeTestMethods(Invoker.java:989)
at org.testng.internal.TestMethodWorker.invokeTestMethods(TestMethodWorker.java:125)
at org.testng.internal.TestMethodWorker.run(TestMethodWorker.java:109)
at org.testng.TestRunner.privateRun(TestRunner.java:648)
at org.testng.TestRunner.run(TestRunner.java:505)
at org.testng.SuiteRunner.runTest(SuiteRunner.java:455)
at org.testng.SuiteRunner.runSequentially(SuiteRunner.java:450)
at org.testng.SuiteRunner.privateRun(SuiteRunner.java:415)
at org.testng.SuiteRunner.run(SuiteRunner.java:364)
at org.testng.SuiteRunnerWorker.runSuite(SuiteRunnerWorker.java:52)
at org.testng.SuiteRunnerWorker.run(SuiteRunnerWorker.java:84)
at org.testng.TestNG.runSuitesSequentially(TestNG.java:1208)
at org.testng.TestNG.runSuitesLocally(TestNG.java:1137)
at org.testng.TestNG.runSuites(TestNG.java:1049)
at org.testng.TestNG.run(TestNG.java:1017)
at org.testng.TestNG.privateMain(TestNG.java:1354)
at org.testng.TestNG.main(TestNG.java:1323)
]]>
            </full-stacktrace>
          </exception> <!-- java.lang.NullPointerException -->
          <reporter-output>
          </reporter-output>
        </test-method> <!-- dataDelete -->
        <test-method status="PASS" signature="doAfterClass()[pri:0, instance:com.edu.lijiaqi.reim.ProcessData@721e0f4f]" name="doAfterClass" is-config="true" duration-ms="3939" started-at="2019-12-18T08:02:41Z" finished-at="2019-12-18T08:02:45Z">
          <reporter-output>
          </reporter-output>
        </test-method> <!-- doAfterClass -->
      </class> <!-- com.edu.lijiaqi.reim.ProcessData -->
      <class name="com.edu.lijiaqi.reim.ReimChat">
        <test-method status="PASS" signature="doBeforeClass()[pri:0, instance:com.edu.lijiaqi.reim.ReimChat@2eee9593]" name="doBeforeClass" is-config="true" duration-ms="5336" started-at="2019-12-18T08:02:07Z" finished-at="2019-12-18T08:02:13Z">
          <reporter-output>
          </reporter-output>
        </test-method> <!-- doBeforeClass -->
        <test-method status="FAIL" signature="chatDemo1(java.lang.String)[pri:0, instance:com.edu.lijiaqi.reim.ReimChat@2eee9593]" name="chatDemo1" duration-ms="16" started-at="2019-12-18T08:02:13Z" description="发送信息" data-provider="data2" finished-at="2019-12-18T08:02:13Z">
          <params>
            <param index="0">
              <value>
                <![CDATA[hello]]>
              </value>
            </param>
          </params>
          <exception class="java.lang.IndexOutOfBoundsException">
            <message>
              <![CDATA[Index: 1, Size: 1]]>
            </message>
            <full-stacktrace>
              <![CDATA[java.lang.IndexOutOfBoundsException: Index: 1, Size: 1
at java.util.ArrayList.rangeCheck(ArrayList.java:657)
at java.util.ArrayList.get(ArrayList.java:433)
at com.webtest.core.WebDriverEngine.switchWidow(WebDriverEngine.java:269)
at com.edu.lijiaqi.reim.ReimChat.InitDemo(Unknown Source)
at com.edu.lijiaqi.reim.ReimChat.chatDemo1(Unknown Source)
at sun.reflect.NativeMethodAccessorImpl.invoke0(Native Method)
at sun.reflect.NativeMethodAccessorImpl.invoke(NativeMethodAccessorImpl.java:62)
at sun.reflect.DelegatingMethodAccessorImpl.invoke(DelegatingMethodAccessorImpl.java:43)
at java.lang.reflect.Method.invoke(Method.java:498)
at org.testng.internal.MethodInvocationHelper.invokeMethod(MethodInvocationHelper.java:124)
at org.testng.internal.Invoker.invokeMethod(Invoker.java:583)
at org.testng.internal.Invoker.invokeTestMethod(Invoker.java:719)
at org.testng.internal.Invoker.invokeTestMethods(Invoker.java:989)
at org.testng.internal.TestMethodWorker.invokeTestMethods(TestMethodWorker.java:125)
at org.testng.internal.TestMethodWorker.run(TestMethodWorker.java:109)
at org.testng.TestRunner.privateRun(TestRunner.java:648)
at org.testng.TestRunner.run(TestRunner.java:505)
at org.testng.SuiteRunner.runTest(SuiteRunner.java:455)
at org.testng.SuiteRunner.runSequentially(SuiteRunner.java:450)
at org.testng.SuiteRunner.privateRun(SuiteRunner.java:415)
at org.testng.SuiteRunner.run(SuiteRunner.java:364)
at org.testng.SuiteRunnerWorker.runSuite(SuiteRunnerWorker.java:52)
at org.testng.SuiteRunnerWorker.run(SuiteRunnerWorker.java:84)
at org.testng.TestNG.runSuitesSequentially(TestNG.java:1208)
at org.testng.TestNG.runSuitesLocally(TestNG.java:1137)
at org.testng.TestNG.runSuites(TestNG.java:1049)
at org.testng.TestNG.run(TestNG.java:1017)
at org.testng.TestNG.privateMain(TestNG.java:1354)
at org.testng.TestNG.main(TestNG.java:1323)
]]>
            </full-stacktrace>
          </exception> <!-- java.lang.IndexOutOfBoundsException -->
          <reporter-output>
          </reporter-output>
        </test-method> <!-- chatDemo1 -->
        <test-method status="FAIL" signature="chatDemo1(java.lang.String)[pri:0, instance:com.edu.lijiaqi.reim.ReimChat@2eee9593]" name="chatDemo1" duration-ms="14" started-at="2019-12-18T08:02:13Z" description="发送信息" data-provider="data2" finished-at="2019-12-18T08:02:13Z">
          <params>
            <param index="0">
              <value>
                <![CDATA[[微笑]]]>
              </value>
            </param>
          </params>
          <exception class="java.lang.IndexOutOfBoundsException">
            <message>
              <![CDATA[Index: 1, Size: 1]]>
            </message>
            <full-stacktrace>
              <![CDATA[java.lang.IndexOutOfBoundsException: Index: 1, Size: 1
at java.util.ArrayList.rangeCheck(ArrayList.java:657)
at java.util.ArrayList.get(ArrayList.java:433)
at com.webtest.core.WebDriverEngine.switchWidow(WebDriverEngine.java:269)
at com.edu.lijiaqi.reim.ReimChat.InitDemo(Unknown Source)
at com.edu.lijiaqi.reim.ReimChat.chatDemo1(Unknown Source)
at sun.reflect.NativeMethodAccessorImpl.invoke0(Native Method)
at sun.reflect.NativeMethodAccessorImpl.invoke(NativeMethodAccessorImpl.java:62)
at sun.reflect.DelegatingMethodAccessorImpl.invoke(DelegatingMethodAccessorImpl.java:43)
at java.lang.reflect.Method.invoke(Method.java:498)
at org.testng.internal.MethodInvocationHelper.invokeMethod(MethodInvocationHelper.java:124)
at org.testng.internal.Invoker.invokeMethod(Invoker.java:583)
at org.testng.internal.Invoker.invokeTestMethod(Invoker.java:719)
at org.testng.internal.Invoker.invokeTestMethods(Invoker.java:989)
at org.testng.internal.TestMethodWorker.invokeTestMethods(TestMethodWorker.java:125)
at org.testng.internal.TestMethodWorker.run(TestMethodWorker.java:109)
at org.testng.TestRunner.privateRun(TestRunner.java:648)
at org.testng.TestRunner.run(TestRunner.java:505)
at org.testng.SuiteRunner.runTest(SuiteRunner.java:455)
at org.testng.SuiteRunner.runSequentially(SuiteRunner.java:450)
at org.testng.SuiteRunner.privateRun(SuiteRunner.java:415)
at org.testng.SuiteRunner.run(SuiteRunner.java:364)
at org.testng.SuiteRunnerWorker.runSuite(SuiteRunnerWorker.java:52)
at org.testng.SuiteRunnerWorker.run(SuiteRunnerWorker.java:84)
at org.testng.TestNG.runSuitesSequentially(TestNG.java:1208)
at org.testng.TestNG.runSuitesLocally(TestNG.java:1137)
at org.testng.TestNG.runSuites(TestNG.java:1049)
at org.testng.TestNG.run(TestNG.java:1017)
at org.testng.TestNG.privateMain(TestNG.java:1354)
at org.testng.TestNG.main(TestNG.java:1323)
]]>
            </full-stacktrace>
          </exception> <!-- java.lang.IndexOutOfBoundsException -->
          <reporter-output>
          </reporter-output>
        </test-method> <!-- chatDemo1 -->
        <test-method status="FAIL" signature="chatDemo1(java.lang.String)[pri:0, instance:com.edu.lijiaqi.reim.ReimChat@2eee9593]" name="chatDemo1" duration-ms="15" started-at="2019-12-18T08:02:13Z" description="发送信息" data-provider="data2" finished-at="2019-12-18T08:02:13Z">
          <params>
            <param index="0">
              <value>
                <![CDATA[script@a?[微笑]]]>
              </value>
            </param>
          </params>
          <exception class="java.lang.IndexOutOfBoundsException">
            <message>
              <![CDATA[Index: 1, Size: 1]]>
            </message>
            <full-stacktrace>
              <![CDATA[java.lang.IndexOutOfBoundsException: Index: 1, Size: 1
at java.util.ArrayList.rangeCheck(ArrayList.java:657)
at java.util.ArrayList.get(ArrayList.java:433)
at com.webtest.core.WebDriverEngine.switchWidow(WebDriverEngine.java:269)
at com.edu.lijiaqi.reim.ReimChat.InitDemo(Unknown Source)
at com.edu.lijiaqi.reim.ReimChat.chatDemo1(Unknown Source)
at sun.reflect.NativeMethodAccessorImpl.invoke0(Native Method)
at sun.reflect.NativeMethodAccessorImpl.invoke(NativeMethodAccessorImpl.java:62)
at sun.reflect.DelegatingMethodAccessorImpl.invoke(DelegatingMethodAccessorImpl.java:43)
at java.lang.reflect.Method.invoke(Method.java:498)
at org.testng.internal.MethodInvocationHelper.invokeMethod(MethodInvocationHelper.java:124)
at org.testng.internal.Invoker.invokeMethod(Invoker.java:583)
at org.testng.internal.Invoker.invokeTestMethod(Invoker.java:719)
at org.testng.internal.Invoker.invokeTestMethods(Invoker.java:989)
at org.testng.internal.TestMethodWorker.invokeTestMethods(TestMethodWorker.java:125)
at org.testng.internal.TestMethodWorker.run(TestMethodWorker.java:109)
at org.testng.TestRunner.privateRun(TestRunner.java:648)
at org.testng.TestRunner.run(TestRunner.java:505)
at org.testng.SuiteRunner.runTest(SuiteRunner.java:455)
at org.testng.SuiteRunner.runSequentially(SuiteRunner.java:450)
at org.testng.SuiteRunner.privateRun(SuiteRunner.java:415)
at org.testng.SuiteRunner.run(SuiteRunner.java:364)
at org.testng.SuiteRunnerWorker.runSuite(SuiteRunnerWorker.java:52)
at org.testng.SuiteRunnerWorker.run(SuiteRunnerWorker.java:84)
at org.testng.TestNG.runSuitesSequentially(TestNG.java:1208)
at org.testng.TestNG.runSuitesLocally(TestNG.java:1137)
at org.testng.TestNG.runSuites(TestNG.java:1049)
at org.testng.TestNG.run(TestNG.java:1017)
at org.testng.TestNG.privateMain(TestNG.java:1354)
at org.testng.TestNG.main(TestNG.java:1323)
]]>
            </full-stacktrace>
          </exception> <!-- java.lang.IndexOutOfBoundsException -->
          <reporter-output>
          </reporter-output>
        </test-method> <!-- chatDemo1 -->
        <test-method status="FAIL" signature="chatDemo2()[pri:0, instance:com.edu.lijiaqi.reim.ReimChat@2eee9593]" name="chatDemo2" duration-ms="9" started-at="2019-12-18T08:02:13Z" description="会话框关闭" finished-at="2019-12-18T08:02:13Z">
          <exception class="java.lang.IndexOutOfBoundsException">
            <message>
              <![CDATA[Index: 1, Size: 1]]>
            </message>
            <full-stacktrace>
              <![CDATA[java.lang.IndexOutOfBoundsException: Index: 1, Size: 1
at java.util.ArrayList.rangeCheck(ArrayList.java:657)
at java.util.ArrayList.get(ArrayList.java:433)
at com.webtest.core.WebDriverEngine.switchWidow(WebDriverEngine.java:269)
at com.edu.lijiaqi.reim.ReimChat.chatDemo2(Unknown Source)
at sun.reflect.NativeMethodAccessorImpl.invoke0(Native Method)
at sun.reflect.NativeMethodAccessorImpl.invoke(NativeMethodAccessorImpl.java:62)
at sun.reflect.DelegatingMethodAccessorImpl.invoke(DelegatingMethodAccessorImpl.java:43)
at java.lang.reflect.Method.invoke(Method.java:498)
at org.testng.internal.MethodInvocationHelper.invokeMethod(MethodInvocationHelper.java:124)
at org.testng.internal.Invoker.invokeMethod(Invoker.java:583)
at org.testng.internal.Invoker.invokeTestMethod(Invoker.java:719)
at org.testng.internal.Invoker.invokeTestMethods(Invoker.java:989)
at org.testng.internal.TestMethodWorker.invokeTestMethods(TestMethodWorker.java:125)
at org.testng.internal.TestMethodWorker.run(TestMethodWorker.java:109)
at org.testng.TestRunner.privateRun(TestRunner.java:648)
at org.testng.TestRunner.run(TestRunner.java:505)
at org.testng.SuiteRunner.runTest(SuiteRunner.java:455)
at org.testng.SuiteRunner.runSequentially(SuiteRunner.java:450)
at org.testng.SuiteRunner.privateRun(SuiteRunner.java:415)
at org.testng.SuiteRunner.run(SuiteRunner.java:364)
at org.testng.SuiteRunnerWorker.runSuite(SuiteRunnerWorker.java:52)
at org.testng.SuiteRunnerWorker.run(SuiteRunnerWorker.java:84)
at org.testng.TestNG.runSuitesSequentially(TestNG.java:1208)
at org.testng.TestNG.runSuitesLocally(TestNG.java:1137)
at org.testng.TestNG.runSuites(TestNG.java:1049)
at org.testng.TestNG.run(TestNG.java:1017)
at org.testng.TestNG.privateMain(TestNG.java:1354)
at org.testng.TestNG.main(TestNG.java:1323)
]]>
            </full-stacktrace>
          </exception> <!-- java.lang.IndexOutOfBoundsException -->
          <reporter-output>
          </reporter-output>
        </test-method> <!-- chatDemo2 -->
        <test-method status="PASS" signature="doAfterClass()[pri:0, instance:com.edu.lijiaqi.reim.ReimChat@2eee9593]" name="doAfterClass" is-config="true" duration-ms="4065" started-at="2019-12-18T08:02:13Z" finished-at="2019-12-18T08:02:17Z">
          <reporter-output>
          </reporter-output>
        </test-method> <!-- doAfterClass -->
      </class> <!-- com.edu.lijiaqi.reim.ReimChat -->
      <class name="com.edu.lijiaqi.reim.ProcessList">
        <test-method status="PASS" signature="doBeforeClass()[pri:0, instance:com.edu.lijiaqi.reim.ProcessList@28864e92]" name="doBeforeClass" is-config="true" duration-ms="5374" started-at="2019-12-18T08:02:45Z" finished-at="2019-12-18T08:02:50Z">
          <reporter-output>
          </reporter-output>
        </test-method> <!-- doBeforeClass -->
        <test-method status="FAIL" signature="listAdd(java.lang.String, java.lang.String, java.lang.String, java.lang.String)[pri:0, instance:com.edu.lijiaqi.reim.ProcessList@28864e92]" name="listAdd" duration-ms="61" started-at="2019-12-18T08:02:51Z" description="新增流程模块" data-provider="data5" finished-at="2019-12-18T08:02:51Z">
          <params>
            <param index="0">
              <value>
                <![CDATA[1a1a]]>
              </value>
            </param>
            <param index="1">
              <value>
                <![CDATA[1a1a]]>
              </value>
            </param>
            <param index="2">
              <value>
                <![CDATA[1a1a]]>
              </value>
            </param>
            <param index="3">
              <value>
                <![CDATA[1a1a]]>
              </value>
            </param>
          </params>
          <exception class="java.lang.AssertionError">
            <message>
              <![CDATA[expected [true] but found [false]]]>
            </message>
            <full-stacktrace>
              <![CDATA[java.lang.AssertionError: expected [true] but found [false]
at org.testng.Assert.fail(Assert.java:96)
at org.testng.Assert.failNotEquals(Assert.java:776)
at org.testng.Assert.assertTrue(Assert.java:44)
at org.testng.Assert.assertTrue(Assert.java:54)
at com.edu.lijiaqi.reim.ProcessList.listAdd(Unknown Source)
at sun.reflect.NativeMethodAccessorImpl.invoke0(Native Method)
at sun.reflect.NativeMethodAccessorImpl.invoke(NativeMethodAccessorImpl.java:62)
at sun.reflect.DelegatingMethodAccessorImpl.invoke(DelegatingMethodAccessorImpl.java:43)
at java.lang.reflect.Method.invoke(Method.java:498)
at org.testng.internal.MethodInvocationHelper.invokeMethod(MethodInvocationHelper.java:124)
at org.testng.internal.Invoker.invokeMethod(Invoker.java:583)
at org.testng.internal.Invoker.invokeTestMethod(Invoker.java:719)
at org.testng.internal.Invoker.invokeTestMethods(Invoker.java:989)
at org.testng.internal.TestMethodWorker.invokeTestMethods(TestMethodWorker.java:125)
at org.testng.internal.TestMethodWorker.run(TestMethodWorker.java:109)
at org.testng.TestRunner.privateRun(TestRunner.java:648)
at org.testng.TestRunner.run(TestRunner.java:505)
at org.testng.SuiteRunner.runTest(SuiteRunner.java:455)
at org.testng.SuiteRunner.runSequentially(SuiteRunner.java:450)
at org.testng.SuiteRunner.privateRun(SuiteRunner.java:415)
at org.testng.SuiteRunner.run(SuiteRunner.java:364)
at org.testng.SuiteRunnerWorker.runSuite(SuiteRunnerWorker.java:52)
at org.testng.SuiteRunnerWorker.run(SuiteRunnerWorker.java:84)
at org.testng.TestNG.runSuitesSequentially(TestNG.java:1208)
at org.testng.TestNG.runSuitesLocally(TestNG.java:1137)
at org.testng.TestNG.runSuites(TestNG.java:1049)
at org.testng.TestNG.run(TestNG.java:1017)
at org.testng.TestNG.privateMain(TestNG.java:1354)
at org.testng.TestNG.main(TestNG.java:1323)
]]>
            </full-stacktrace>
          </exception> <!-- java.lang.AssertionError -->
          <reporter-output>
          </reporter-output>
        </test-method> <!-- listAdd -->
        <test-method status="FAIL" signature="listAdd(java.lang.String, java.lang.String, java.lang.String, java.lang.String)[pri:0, instance:com.edu.lijiaqi.reim.ProcessList@28864e92]" name="listAdd" duration-ms="52" started-at="2019-12-18T08:02:51Z" description="新增流程模块" data-provider="data5" finished-at="2019-12-18T08:02:51Z">
          <params>
            <param index="0">
              <value>
                <![CDATA[哈哈]]>
              </value>
            </param>
            <param index="1">
              <value>
                <![CDATA[嘿嘿]]>
              </value>
            </param>
            <param index="2">
              <value>
                <![CDATA[啦啦]]>
              </value>
            </param>
            <param index="3">
              <value>
                <![CDATA[asd]]>
              </value>
            </param>
          </params>
          <exception class="java.lang.AssertionError">
            <message>
              <![CDATA[expected [true] but found [false]]]>
            </message>
            <full-stacktrace>
              <![CDATA[java.lang.AssertionError: expected [true] but found [false]
at org.testng.Assert.fail(Assert.java:96)
at org.testng.Assert.failNotEquals(Assert.java:776)
at org.testng.Assert.assertTrue(Assert.java:44)
at org.testng.Assert.assertTrue(Assert.java:54)
at com.edu.lijiaqi.reim.ProcessList.listAdd(Unknown Source)
at sun.reflect.NativeMethodAccessorImpl.invoke0(Native Method)
at sun.reflect.NativeMethodAccessorImpl.invoke(NativeMethodAccessorImpl.java:62)
at sun.reflect.DelegatingMethodAccessorImpl.invoke(DelegatingMethodAccessorImpl.java:43)
at java.lang.reflect.Method.invoke(Method.java:498)
at org.testng.internal.MethodInvocationHelper.invokeMethod(MethodInvocationHelper.java:124)
at org.testng.internal.Invoker.invokeMethod(Invoker.java:583)
at org.testng.internal.Invoker.invokeTestMethod(Invoker.java:719)
at org.testng.internal.Invoker.invokeTestMethods(Invoker.java:989)
at org.testng.internal.TestMethodWorker.invokeTestMethods(TestMethodWorker.java:125)
at org.testng.internal.TestMethodWorker.run(TestMethodWorker.java:109)
at org.testng.TestRunner.privateRun(TestRunner.java:648)
at org.testng.TestRunner.run(TestRunner.java:505)
at org.testng.SuiteRunner.runTest(SuiteRunner.java:455)
at org.testng.SuiteRunner.runSequentially(SuiteRunner.java:450)
at org.testng.SuiteRunner.privateRun(SuiteRunner.java:415)
at org.testng.SuiteRunner.run(SuiteRunner.java:364)
at org.testng.SuiteRunnerWorker.runSuite(SuiteRunnerWorker.java:52)
at org.testng.SuiteRunnerWorker.run(SuiteRunnerWorker.java:84)
at org.testng.TestNG.runSuitesSequentially(TestNG.java:1208)
at org.testng.TestNG.runSuitesLocally(TestNG.java:1137)
at org.testng.TestNG.runSuites(TestNG.java:1049)
at org.testng.TestNG.run(TestNG.java:1017)
at org.testng.TestNG.privateMain(TestNG.java:1354)
at org.testng.TestNG.main(TestNG.java:1323)
]]>
            </full-stacktrace>
          </exception> <!-- java.lang.AssertionError -->
          <reporter-output>
          </reporter-output>
        </test-method> <!-- listAdd -->
        <test-method status="PASS" signature="listChange()[pri:0, instance:com.edu.lijiaqi.reim.ProcessList@28864e92]" name="listChange" duration-ms="44" started-at="2019-12-18T08:02:51Z" description="编辑流程模块" finished-at="2019-12-18T08:02:51Z">
          <reporter-output>
          </reporter-output>
        </test-method> <!-- listChange -->
        <test-method status="FAIL" signature="listDelete()[pri:0, instance:com.edu.lijiaqi.reim.ProcessList@28864e92]" name="listDelete" duration-ms="20" started-at="2019-12-18T08:02:51Z" description="删除流程模块" finished-at="2019-12-18T08:02:51Z">
          <exception class="java.lang.AssertionError">
            <message>
              <![CDATA[expected [true] but found [false]]]>
            </message>
            <full-stacktrace>
              <![CDATA[java.lang.AssertionError: expected [true] but found [false]
at org.testng.Assert.fail(Assert.java:96)
at org.testng.Assert.failNotEquals(Assert.java:776)
at org.testng.Assert.assertTrue(Assert.java:44)
at org.testng.Assert.assertTrue(Assert.java:54)
at com.edu.lijiaqi.reim.ProcessList.listDelete(Unknown Source)
at sun.reflect.NativeMethodAccessorImpl.invoke0(Native Method)
at sun.reflect.NativeMethodAccessorImpl.invoke(NativeMethodAccessorImpl.java:62)
at sun.reflect.DelegatingMethodAccessorImpl.invoke(DelegatingMethodAccessorImpl.java:43)
at java.lang.reflect.Method.invoke(Method.java:498)
at org.testng.internal.MethodInvocationHelper.invokeMethod(MethodInvocationHelper.java:124)
at org.testng.internal.Invoker.invokeMethod(Invoker.java:583)
at org.testng.internal.Invoker.invokeTestMethod(Invoker.java:719)
at org.testng.internal.Invoker.invokeTestMethods(Invoker.java:989)
at org.testng.internal.TestMethodWorker.invokeTestMethods(TestMethodWorker.java:125)
at org.testng.internal.TestMethodWorker.run(TestMethodWorker.java:109)
at org.testng.TestRunner.privateRun(TestRunner.java:648)
at org.testng.TestRunner.run(TestRunner.java:505)
at org.testng.SuiteRunner.runTest(SuiteRunner.java:455)
at org.testng.SuiteRunner.runSequentially(SuiteRunner.java:450)
at org.testng.SuiteRunner.privateRun(SuiteRunner.java:415)
at org.testng.SuiteRunner.run(SuiteRunner.java:364)
at org.testng.SuiteRunnerWorker.runSuite(SuiteRunnerWorker.java:52)
at org.testng.SuiteRunnerWorker.run(SuiteRunnerWorker.java:84)
at org.testng.TestNG.runSuitesSequentially(TestNG.java:1208)
at org.testng.TestNG.runSuitesLocally(TestNG.java:1137)
at org.testng.TestNG.runSuites(TestNG.java:1049)
at org.testng.TestNG.run(TestNG.java:1017)
at org.testng.TestNG.privateMain(TestNG.java:1354)
at org.testng.TestNG.main(TestNG.java:1323)
]]>
            </full-stacktrace>
          </exception> <!-- java.lang.AssertionError -->
          <reporter-output>
          </reporter-output>
        </test-method> <!-- listDelete -->
        <test-method status="PASS" signature="doAfterClass()[pri:0, instance:com.edu.lijiaqi.reim.ProcessList@28864e92]" name="doAfterClass" is-config="true" duration-ms="3910" started-at="2019-12-18T08:02:51Z" finished-at="2019-12-18T08:02:55Z">
          <reporter-output>
          </reporter-output>
        </test-method> <!-- doAfterClass -->
      </class> <!-- com.edu.lijiaqi.reim.ProcessList -->
      <class name="com.edu.lijiaqi.reim.ReimSearch">
        <test-method status="PASS" signature="doBeforeClass()[pri:0, instance:com.edu.lijiaqi.reim.ReimSearch@3ab39c39]" name="doBeforeClass" is-config="true" duration-ms="7991" started-at="2019-12-18T08:01:55Z" finished-at="2019-12-18T08:02:03Z">
          <reporter-output>
          </reporter-output>
        </test-method> <!-- doBeforeClass -->
        <test-method status="FAIL" signature="searchDemo1(java.lang.String)[pri:0, instance:com.edu.lijiaqi.reim.ReimSearch@3ab39c39]" name="searchDemo1" duration-ms="19" started-at="2019-12-18T08:02:03Z" description="输入搜索" data-provider="data3" finished-at="2019-12-18T08:02:03Z">
          <params>
            <param index="0">
              <value>
                <![CDATA[貂蝉]]>
              </value>
            </param>
          </params>
          <exception class="java.lang.IndexOutOfBoundsException">
            <message>
              <![CDATA[Index: 1, Size: 1]]>
            </message>
            <full-stacktrace>
              <![CDATA[java.lang.IndexOutOfBoundsException: Index: 1, Size: 1
at java.util.ArrayList.rangeCheck(ArrayList.java:657)
at java.util.ArrayList.get(ArrayList.java:433)
at com.webtest.core.WebDriverEngine.switchWidow(WebDriverEngine.java:269)
at com.edu.lijiaqi.reim.ReimSearch.InitDemo(Unknown Source)
at com.edu.lijiaqi.reim.ReimSearch.searchDemo1(Unknown Source)
at sun.reflect.NativeMethodAccessorImpl.invoke0(Native Method)
at sun.reflect.NativeMethodAccessorImpl.invoke(NativeMethodAccessorImpl.java:62)
at sun.reflect.DelegatingMethodAccessorImpl.invoke(DelegatingMethodAccessorImpl.java:43)
at java.lang.reflect.Method.invoke(Method.java:498)
at org.testng.internal.MethodInvocationHelper.invokeMethod(MethodInvocationHelper.java:124)
at org.testng.internal.Invoker.invokeMethod(Invoker.java:583)
at org.testng.internal.Invoker.invokeTestMethod(Invoker.java:719)
at org.testng.internal.Invoker.invokeTestMethods(Invoker.java:989)
at org.testng.internal.TestMethodWorker.invokeTestMethods(TestMethodWorker.java:125)
at org.testng.internal.TestMethodWorker.run(TestMethodWorker.java:109)
at org.testng.TestRunner.privateRun(TestRunner.java:648)
at org.testng.TestRunner.run(TestRunner.java:505)
at org.testng.SuiteRunner.runTest(SuiteRunner.java:455)
at org.testng.SuiteRunner.runSequentially(SuiteRunner.java:450)
at org.testng.SuiteRunner.privateRun(SuiteRunner.java:415)
at org.testng.SuiteRunner.run(SuiteRunner.java:364)
at org.testng.SuiteRunnerWorker.runSuite(SuiteRunnerWorker.java:52)
at org.testng.SuiteRunnerWorker.run(SuiteRunnerWorker.java:84)
at org.testng.TestNG.runSuitesSequentially(TestNG.java:1208)
at org.testng.TestNG.runSuitesLocally(TestNG.java:1137)
at org.testng.TestNG.runSuites(TestNG.java:1049)
at org.testng.TestNG.run(TestNG.java:1017)
at org.testng.TestNG.privateMain(TestNG.java:1354)
at org.testng.TestNG.main(TestNG.java:1323)
]]>
            </full-stacktrace>
          </exception> <!-- java.lang.IndexOutOfBoundsException -->
          <reporter-output>
          </reporter-output>
        </test-method> <!-- searchDemo1 -->
        <test-method status="FAIL" signature="searchDemo1(java.lang.String)[pri:0, instance:com.edu.lijiaqi.reim.ReimSearch@3ab39c39]" name="searchDemo1" duration-ms="15" started-at="2019-12-18T08:02:03Z" description="输入搜索" data-provider="data3" finished-at="2019-12-18T08:02:03Z">
          <params>
            <param index="0">
              <value>
                <![CDATA[貂]]>
              </value>
            </param>
          </params>
          <exception class="java.lang.IndexOutOfBoundsException">
            <message>
              <![CDATA[Index: 1, Size: 1]]>
            </message>
            <full-stacktrace>
              <![CDATA[java.lang.IndexOutOfBoundsException: Index: 1, Size: 1
at java.util.ArrayList.rangeCheck(ArrayList.java:657)
at java.util.ArrayList.get(ArrayList.java:433)
at com.webtest.core.WebDriverEngine.switchWidow(WebDriverEngine.java:269)
at com.edu.lijiaqi.reim.ReimSearch.InitDemo(Unknown Source)
at com.edu.lijiaqi.reim.ReimSearch.searchDemo1(Unknown Source)
at sun.reflect.NativeMethodAccessorImpl.invoke0(Native Method)
at sun.reflect.NativeMethodAccessorImpl.invoke(NativeMethodAccessorImpl.java:62)
at sun.reflect.DelegatingMethodAccessorImpl.invoke(DelegatingMethodAccessorImpl.java:43)
at java.lang.reflect.Method.invoke(Method.java:498)
at org.testng.internal.MethodInvocationHelper.invokeMethod(MethodInvocationHelper.java:124)
at org.testng.internal.Invoker.invokeMethod(Invoker.java:583)
at org.testng.internal.Invoker.invokeTestMethod(Invoker.java:719)
at org.testng.internal.Invoker.invokeTestMethods(Invoker.java:989)
at org.testng.internal.TestMethodWorker.invokeTestMethods(TestMethodWorker.java:125)
at org.testng.internal.TestMethodWorker.run(TestMethodWorker.java:109)
at org.testng.TestRunner.privateRun(TestRunner.java:648)
at org.testng.TestRunner.run(TestRunner.java:505)
at org.testng.SuiteRunner.runTest(SuiteRunner.java:455)
at org.testng.SuiteRunner.runSequentially(SuiteRunner.java:450)
at org.testng.SuiteRunner.privateRun(SuiteRunner.java:415)
at org.testng.SuiteRunner.run(SuiteRunner.java:364)
at org.testng.SuiteRunnerWorker.runSuite(SuiteRunnerWorker.java:52)
at org.testng.SuiteRunnerWorker.run(SuiteRunnerWorker.java:84)
at org.testng.TestNG.runSuitesSequentially(TestNG.java:1208)
at org.testng.TestNG.runSuitesLocally(TestNG.java:1137)
at org.testng.TestNG.runSuites(TestNG.java:1049)
at org.testng.TestNG.run(TestNG.java:1017)
at org.testng.TestNG.privateMain(TestNG.java:1354)
at org.testng.TestNG.main(TestNG.java:1323)
]]>
            </full-stacktrace>
          </exception> <!-- java.lang.IndexOutOfBoundsException -->
          <reporter-output>
          </reporter-output>
        </test-method> <!-- searchDemo1 -->
        <test-method status="FAIL" signature="searchDemo1(java.lang.String)[pri:0, instance:com.edu.lijiaqi.reim.ReimSearch@3ab39c39]" name="searchDemo1" duration-ms="16" started-at="2019-12-18T08:02:03Z" description="输入搜索" data-provider="data3" finished-at="2019-12-18T08:02:03Z">
          <params>
            <param index="0">
              <value>
                <![CDATA[考勤打卡]]>
              </value>
            </param>
          </params>
          <exception class="java.lang.IndexOutOfBoundsException">
            <message>
              <![CDATA[Index: 1, Size: 1]]>
            </message>
            <full-stacktrace>
              <![CDATA[java.lang.IndexOutOfBoundsException: Index: 1, Size: 1
at java.util.ArrayList.rangeCheck(ArrayList.java:657)
at java.util.ArrayList.get(ArrayList.java:433)
at com.webtest.core.WebDriverEngine.switchWidow(WebDriverEngine.java:269)
at com.edu.lijiaqi.reim.ReimSearch.InitDemo(Unknown Source)
at com.edu.lijiaqi.reim.ReimSearch.searchDemo1(Unknown Source)
at sun.reflect.NativeMethodAccessorImpl.invoke0(Native Method)
at sun.reflect.NativeMethodAccessorImpl.invoke(NativeMethodAccessorImpl.java:62)
at sun.reflect.DelegatingMethodAccessorImpl.invoke(DelegatingMethodAccessorImpl.java:43)
at java.lang.reflect.Method.invoke(Method.java:498)
at org.testng.internal.MethodInvocationHelper.invokeMethod(MethodInvocationHelper.java:124)
at org.testng.internal.Invoker.invokeMethod(Invoker.java:583)
at org.testng.internal.Invoker.invokeTestMethod(Invoker.java:719)
at org.testng.internal.Invoker.invokeTestMethods(Invoker.java:989)
at org.testng.internal.TestMethodWorker.invokeTestMethods(TestMethodWorker.java:125)
at org.testng.internal.TestMethodWorker.run(TestMethodWorker.java:109)
at org.testng.TestRunner.privateRun(TestRunner.java:648)
at org.testng.TestRunner.run(TestRunner.java:505)
at org.testng.SuiteRunner.runTest(SuiteRunner.java:455)
at org.testng.SuiteRunner.runSequentially(SuiteRunner.java:450)
at org.testng.SuiteRunner.privateRun(SuiteRunner.java:415)
at org.testng.SuiteRunner.run(SuiteRunner.java:364)
at org.testng.SuiteRunnerWorker.runSuite(SuiteRunnerWorker.java:52)
at org.testng.SuiteRunnerWorker.run(SuiteRunnerWorker.java:84)
at org.testng.TestNG.runSuitesSequentially(TestNG.java:1208)
at org.testng.TestNG.runSuitesLocally(TestNG.java:1137)
at org.testng.TestNG.runSuites(TestNG.java:1049)
at org.testng.TestNG.run(TestNG.java:1017)
at org.testng.TestNG.privateMain(TestNG.java:1354)
at org.testng.TestNG.main(TestNG.java:1323)
]]>
            </full-stacktrace>
          </exception> <!-- java.lang.IndexOutOfBoundsException -->
          <reporter-output>
          </reporter-output>
        </test-method> <!-- searchDemo1 -->
        <test-method status="FAIL" signature="searchDemo1(java.lang.String)[pri:0, instance:com.edu.lijiaqi.reim.ReimSearch@3ab39c39]" name="searchDemo1" duration-ms="23" started-at="2019-12-18T08:02:03Z" description="输入搜索" data-provider="data3" finished-at="2019-12-18T08:02:03Z">
          <params>
            <param index="0">
              <value>
                <![CDATA[打卡]]>
              </value>
            </param>
          </params>
          <exception class="java.lang.IndexOutOfBoundsException">
            <message>
              <![CDATA[Index: 1, Size: 1]]>
            </message>
            <full-stacktrace>
              <![CDATA[java.lang.IndexOutOfBoundsException: Index: 1, Size: 1
at java.util.ArrayList.rangeCheck(ArrayList.java:657)
at java.util.ArrayList.get(ArrayList.java:433)
at com.webtest.core.WebDriverEngine.switchWidow(WebDriverEngine.java:269)
at com.edu.lijiaqi.reim.ReimSearch.InitDemo(Unknown Source)
at com.edu.lijiaqi.reim.ReimSearch.searchDemo1(Unknown Source)
at sun.reflect.NativeMethodAccessorImpl.invoke0(Native Method)
at sun.reflect.NativeMethodAccessorImpl.invoke(NativeMethodAccessorImpl.java:62)
at sun.reflect.DelegatingMethodAccessorImpl.invoke(DelegatingMethodAccessorImpl.java:43)
at java.lang.reflect.Method.invoke(Method.java:498)
at org.testng.internal.MethodInvocationHelper.invokeMethod(MethodInvocationHelper.java:124)
at org.testng.internal.Invoker.invokeMethod(Invoker.java:583)
at org.testng.internal.Invoker.invokeTestMethod(Invoker.java:719)
at org.testng.internal.Invoker.invokeTestMethods(Invoker.java:989)
at org.testng.internal.TestMethodWorker.invokeTestMethods(TestMethodWorker.java:125)
at org.testng.internal.TestMethodWorker.run(TestMethodWorker.java:109)
at org.testng.TestRunner.privateRun(TestRunner.java:648)
at org.testng.TestRunner.run(TestRunner.java:505)
at org.testng.SuiteRunner.runTest(SuiteRunner.java:455)
at org.testng.SuiteRunner.runSequentially(SuiteRunner.java:450)
at org.testng.SuiteRunner.privateRun(SuiteRunner.java:415)
at org.testng.SuiteRunner.run(SuiteRunner.java:364)
at org.testng.SuiteRunnerWorker.runSuite(SuiteRunnerWorker.java:52)
at org.testng.SuiteRunnerWorker.run(SuiteRunnerWorker.java:84)
at org.testng.TestNG.runSuitesSequentially(TestNG.java:1208)
at org.testng.TestNG.runSuitesLocally(TestNG.java:1137)
at org.testng.TestNG.runSuites(TestNG.java:1049)
at org.testng.TestNG.run(TestNG.java:1017)
at org.testng.TestNG.privateMain(TestNG.java:1354)
at org.testng.TestNG.main(TestNG.java:1323)
]]>
            </full-stacktrace>
          </exception> <!-- java.lang.IndexOutOfBoundsException -->
          <reporter-output>
          </reporter-output>
        </test-method> <!-- searchDemo1 -->
        <test-method status="PASS" signature="doAfterClass()[pri:0, instance:com.edu.lijiaqi.reim.ReimSearch@3ab39c39]" name="doAfterClass" is-config="true" duration-ms="3957" started-at="2019-12-18T08:02:03Z" finished-at="2019-12-18T08:02:07Z">
          <reporter-output>
          </reporter-output>
        </test-method> <!-- doAfterClass -->
      </class> <!-- com.edu.lijiaqi.reim.ReimSearch -->
    </test> <!-- test2 -->
  </suite> <!-- TestNGSuite -->
</testng-results>
